Traceback (most recent call last):
Testing browser-get-news...
--------------------------------------------------

Topic: ai
Sources tried: 3
Successful: 1
Method: direct_site_with_extraction
  File "C:\Users\atchi\spec-kit\mcp-ai-agent\test_browser_news.py", line 42, in <module>
    asyncio.run(test_news())
  File "C:\Users\atchi\AppData\Local\Programs\Python\Python311\Lib\asyncio\runners.py", line 190, in run
    return runner.run(main)
           ^^^^^^^^^^^^^^^^
  File "C:\Users\atchi\AppData\Local\Programs\Python\Python311\Lib\asyncio\runners.py", line 118, in run
    return self._loop.run_until_complete(task)
           ^^^^^^^^^^^^^^^^^^^^^^^^^^^^^^^^^^^
  File "C:\Users\atchi\AppData\Local\Programs\Python\Python311\Lib\asyncio\base_events.py", line 654, in run_until_complete
    return future.result()
           ^^^^^^^^^^^^^^^
  File "C:\Users\atchi\spec-kit\mcp-ai-agent\test_browser_news.py", line 24, in test_news
    print("\n\u2713 SUCCESS! Got news content:")
  File "C:\Users\atchi\AppData\Local\Programs\Python\Python311\Lib\encodings\cp1252.py", line 19, in encode
    return codecs.charmap_encode(input,self.errors,encoding_table)[0]
           ^^^^^^^^^^^^^^^^^^^^^^^^^^^^^^^^^^^^^^^^^^^^^^^^^^^^^^^
UnicodeEncodeError: 'charmap' codec can't encode character '\u2713' in position 2: character maps to <undefined>
Exception ignored in: <function BaseSubprocessTransport.__del__ at 0x0000018D118E9580>
Traceback (most recent call last):
  File "C:\Users\atchi\AppData\Local\Programs\Python\Python311\Lib\asyncio\base_subprocess.py", line 126, in __del__
  File "C:\Users\atchi\AppData\Local\Programs\Python\Python311\Lib\asyncio\base_subprocess.py", line 104, in close
  File "C:\Users\atchi\AppData\Local\Programs\Python\Python311\Lib\asyncio\proactor_events.py", line 109, in close
  File "C:\Users\atchi\AppData\Local\Programs\Python\Python311\Lib\asyncio\base_events.py", line 762, in call_soon
  File "C:\Users\atchi\AppData\Local\Programs\Python\Python311\Lib\asyncio\base_events.py", line 520, in _check_closed
RuntimeError: Event loop is closed
